Workbook
Name Slicer_Team: #N/A

Sheet Raw
A1: Team | B1: AgentID | C1: Day | D1: Shift | E1: Experience | F1: CallsHandled | G1: AvgCallDuration | H1: EscalationRate | I1: FCRRate | J1: CSATScore | K1: OvertimeHours | L1: CostPerCall | M1: Total Escalations | N1: Total FCRRate
A2: Team A | B2: Agent_1 | C2: Monday | D2: Morning | E2: 3-6 months | F2: 58 | G2: 6.54 | H2: 0.1 | I2: 0.82 | J2: 3.63 | K2: 0 | L2: 24.81 | M2: =SUM(F2*H2) -> 5.8 | N2: =SUM(I2*F2) -> 47.56
A3: Team A | B3: Agent_1 | C3: Monday | D3: Afternoon | E3: 3-6 months | F3: 69 | G3: 5.38 | H3: 0.11 | I3: 0.75 | J3: 4.76 | K3: 2 | L3: 27.07 | M3: =SUM(F3*H3) -> 7.59 | N3: =SUM(I3*F3) -> 51.75
A4: Team A | B4: Agent_1 | C4: Monday | D4: Evening | E4: 0-3 months | F4: 50 | G4: 7.46 | H4: 0.05 | I4: 0.61 | J4: 4.18 | K4: 0 | L4: 26.19 | M4: =SUM(F4*H4) -> 2.5 | N4: =SUM(I4*F4) -> 30.5
A5: Team A | B5: Agent_1 | C5: Tuesday | D5: Morning | E5: 0-3 months | F5: 45 | G5: 7.54 | H5: 0.11 | I5: 0.76 | J5: 4.3 | K5: 0 | L5: 26.31 | M5: =SUM(F5*H5) -> 4.95 | N5: =SUM(I5*F5) -> 34.2
A6: Team A | B6: Agent_1 | C6: Tuesday | D6: Afternoon | E6: 6+ months | F6: 32 | G6: 6.42 | H6: 0.08 | I6: 0.75 | J6: 4.72 | K6: 0 | L6: 24.63 | M6: =SUM(F6*H6) -> 2.56 | N6: =SUM(I6*F6) -> 24
A7: Team A | B7: Agent_1 | C7: Tuesday | D7: Evening | E7: 3-6 months | F7: 55 | G7: 6.83 | H7: 0.03 | I7: 0.77 | J7: 4.07 | K7: 0 | L7: 25.24 | M7: =SUM(F7*H7) -> 1.65 | N7: =SUM(I7*F7) -> 42.35
A8: Team A | B8: Agent_1 | C8: Wednesday | D8: Morning | E8: 3-6 months | F8: 76 | G8: 5.61 | H8: 0.04 | I8: 0.86 | J8: 4.05 | K8: 0 | L8: 23.42 | M8: =SUM(F8*H8) -> 3.04 | N8: =SUM(I8*F8) -> 65.36
A9: Team A | B9: Agent_1 | C9: Wednesday | D9: Afternoon | E9: 3-6 months | F9: 58 | G9: 4.84 | H9: 0.15 | I9: 0.87 | J9: 4.72 | K9: 2 | L9: 26.26 | M9: =SUM(F9*H9) -> 8.7 | N9: =SUM(I9*F9) -> 50.46
A10: Team A | B10: Agent_1 | C10: Wednesday | D10: Evening | E10: 3-6 months | F10: 77 | G10: 6.75 | H10: 0.09 | I10: 0.84 | J10: 4.6 | K10: 1 | L10: 27.12 | M10: =SUM(F10*H10) -> 6.93 | N10: =SUM(I10*F10) -> 64.68
A11: Team A | B11: Agent_1 | C11: Thursday | D11: Morning | E11: 3-6 months | F11: 53 | G11: 4.16 | H11: 0.07 | I11: 0.79 | J11: 4.21 | K11: 0 | L11: 21.24 | M11: =SUM(F11*H11) -> 3.71 | N11: =SUM(I11*F11) -> 41.87
A12: Team A | B12: Agent_1 | C12: Thursday | D12: Afternoon | E12: 6+ months | F12: 30 | G12: 5.96 | H12: 0.07 | I12: 0.79 | J12: 3.52 | K12: 0 | L12: 23.94 | M12: =SUM(F12*H12) -> 2.1 | N12: =SUM(I12*F12) -> 23.7
A13: Team A | B13: Agent_1 | C13: Thursday | D13: Evening | E13: 6+ months | F13: 64 | G13: 5.72 | H13: 0.12 | I13: 0.62 | J13: 3.97 | K13: 0 | L13: 23.58 | M13: =SUM(F13*H13) -> 7.68 | N13: =SUM(I13*F13) -> 39.68
... A451: Team C | B451: Agent_10 | C451: Friday | D451: Evening | E451: 6+ months | F451: 67 | G451: 5.7 | H451: 0.07 | I451: 0.72 | J451: 3.87 | K451: 1 | L451: 25.55 | M451: =SUM(F451*H451) -> 4.69 | N451: =SUM(I451*F451) -> 48.24

Sheet Analysis
E3: ConnectTel Call Centre Analysis
A6: PIVOT TABLE 1 | E6: GRAPH 1
A7: Shift | B7: Number of CallsHandled | H7: * Mornings produce peak calls handled
A8: Evening | B8: 7918 | H8: * Afternoons have less peak calls handled
A9: Afternoon | B9: 7989 | H9: * However, there is less overtime shifts in the morning
A10: Morning | B10: 8431
A11: Grand Total | B11: 24338 | H11: * Team B has the most overtime in the afternoon than in the morning
H12: * Team B has to add more hours for morning shift and less for afternoon
E19: GRAPH 2
A20: PIVOT TABLE 2
A21: Shift | B21: Total OvertimeHours
A22: Morning | B22: 94
A23: Evening | B23: 95
A24: Afternoon | B24: 101
A25: Grand Total | B25: 290
B36: PIVOT TABLE 3 | F36: Graph 3
A37: Team | B37: Avgerage CallDuration | C37: Number of Calls Handled | D37: Average Cost Per Call
A38: Team C | B38: 897.37 | C38: 8229 | D38: 25.240333
A39: Team B | B39: 1128.56 | C39: 8082 | D39: 27.5658
A40: Team A | B40: 909.38 | C40: 8027 | D40: 25.413867
C53: Table 1
B55: Team | C55: Total Calls Handled | D55: Average Call duration | E55: AverageCostPerCall | F55: Total Escalations | G55: Overall Escalation Rate | H55: Overall FCR Rate | I55: Overall FCR Rate2
B56: Team A | C56: =SUMIF(Raw!A:A,Table14[[#This Row],[Team]],Raw!F:F) -> 8027 | D56: =AVERAGEIF(Raw!A:A,Table14[[#This Row],[Team]],Raw!G:G) -> 6.0625333 | E56: =AVERAGEIF(Raw!A:A,Table14[[#This Row],[Team]],Raw!L:L) -> 25.413867 | F56: =SUMIF(Raw!A:A,Table14[[#This Row],[Team]],Raw!M:M) -> 944.22 | G56: =Table14[[#This Row],[Total Escalations]]/Table14[[#This Row],[Total Calls Handled]]*100 -> 11.76305 | H56: =SUMIF(Raw!A:A,Table14[[#This Row],[Team]],Raw!N:N) -> 6361.31 | I56: =Table14[[#This Row],[Overall FCR Rate]]/Table14[[#This Row],[Total Calls Handled]]*100 -> 79.24891
B57: Team B | C57: =SUMIF(Raw!A:A,Table14[[#This Row],[Team]],Raw!F:F) -> 8082 | D57: =AVERAGEIF(Raw!A:A,Table14[[#This Row],[Team]],Raw!G:G) -> 7.5237333 | E57: =AVERAGEIF(Raw!A:A,Table14[[#This Row],[Team]],Raw!L:L) -> 27.5658 | F57: =SUMIF(Raw!A:A,Table14[[#This Row],[Team]],Raw!M:M) -> 855.4 | G57: =Table14[[#This Row],[Total Escalations]]/Table14[[#This Row],[Total Calls Handled]]*100 -> 10.584014 | H57: =SUMIF(Raw!A:A,Table14[[#This Row],[Team]],Raw!N:N) -> 6456.37 | I57: =Table14[[#This Row],[Overall FCR Rate]]/Table14[[#This Row],[Total Calls Handled]]*100 -> 79.885796
B58: Team C | C58: =SUMIF(Raw!A:A,Table14[[#This Row],[Team]],Raw!F:F) -> 8229 | D58: =AVERAGEIF(Raw!A:A,Table14[[#This Row],[Team]],Raw!G:G) -> 5.9824667 | E58: =AVERAGEIF(Raw!A:A,Table14[[#This Row],[Team]],Raw!L:L) -> 25.240333 | F58: =SUMIF(Raw!A:A,Table14[[#This Row],[Team]],Raw!M:M) -> 927.18 | G58: =Table14[[#This Row],[Total Escalations]]/Table14[[#This Row],[Total Calls Handled]]*100 -> 11.267226 | H58: =SUMIF(Raw!A:A,Table14[[#This Row],[Team]],Raw!N:N) -> 6440.85 | I58: =Table14[[#This Row],[Overall FCR Rate]]/Table14[[#This Row],[Total Calls Handled]]*100 -> 78.270142
C61: Table 2
B63: Team | C63: Agent | D63: Total calls Handled | E63: Average Call duration | F63: Average Cost Per call | G63: Num Escalations | H63: Overall EscalateRte | I63: Num FCR | J63: Overall FCRRate | K63: Average CSATScore
B64: Team B | C64: Agent_10 | D64: =SUMIFS(Raw!F:F, Raw!A:A, Table2185[[#This Row],[Team]], Raw!B:B, Table2185[[#This Row],[Agent]]) -> 771 | E64: =SUMIFS(Raw!G:G,Raw!A:A,Table2185[[#This Row],[Team]],Raw!B:B,Table2185[[#This Row],[Agent]]) -> 105.11 | F64: =AVERAGEIFS(Raw!L:L,Raw!A:A,B64,Raw!B:B,Table2185[[#This Row],[Agent]]) -> 26.710667 | G64: =SUMIFS(Raw!M:M,Raw!A:A,Table2185[[#This Row],[Team]],Raw!B:B,Table2185[[#This Row],[Agent]]) -> 67.64 | H64: =(Table2185[[#This Row],[Num Escalations]]/Table2185[[#This Row],[Total calls Handled]]) -> 0.08773022 | I64: =SUMIFS(Raw!N:N,Raw!A:A,Table2185[[#This Row],[Team]],Raw!B:B,Table2185[[#This Row],[Agent]]) -> 635.76 | J64: =Table2185[[#This Row],[Num FCR]]/Table2185[[#This Row],[Total calls Handled]] -> 0.82459144 | K64: =AVERAGEIFS(Raw!J:J,Raw!A:A,Table2185[[#This Row],[Team]],Raw!B:B,Table2185[[#This Row],[Agent]]) -> 4.068
B65: Team A | C65: Agent_2 | D65: =SUMIFS(Raw!F:F, Raw!A:A, Table2185[[#This Row],[Team]], Raw!B:B, Table2185[[#This Row],[Agent]]) -> 830 | E65: =SUMIFS(Raw!G:G,Raw!A:A,Table2185[[#This Row],[Team]],Raw!B:B,Table2185[[#This Row],[Agent]]) -> 91.57 | F65: =AVERAGEIFS(Raw!L:L,Raw!A:A,B66,Raw!B:B,Table2185[[#This Row],[Agent]]) -> 27.233333 | G65: =SUMIFS(Raw!M:M,Raw!A:A,Table2185[[#This Row],[Team]],Raw!B:B,Table2185[[#This Row],[Agent]]) -> 84.1 | H65: =(Table2185[[#This Row],[Num Escalations]]/Table2185[[#This Row],[Total calls Handled]]) -> 0.1013253 | I65: =SUMIFS(Raw!N:N,Raw!A:A,Table2185[[#This Row],[Team]],Raw!B:B,Table2185[[#This Row],[Agent]]) -> 682.11 | J65: =Table2185[[#This Row],[Num FCR]]/Table2185[[#This Row],[Total calls Handled]] -> 0.82181928 | K65: =AVERAGEIFS(Raw!J:J,Raw!A:A,Table2185[[#This Row],[Team]],Raw!B:B,Table2185[[#This Row],[Agent]]) -> 4.2113333
B66: Team B | C66: Agent_1 | D66: =SUMIFS(Raw!F:F, Raw!A:A, Table2185[[#This Row],[Team]], Raw!B:B, Table2185[[#This Row],[Agent]]) -> 844 | E66: =SUMIFS(Raw!G:G,Raw!A:A,Table2185[[#This Row],[Team]],Raw!B:B,Table2185[[#This Row],[Agent]]) -> 110.4 | F66: =AVERAGEIFS(Raw!L:L,Raw!A:A,B66,Raw!B:B,Table2185[[#This Row],[Agent]]) -> 27.774 | G66: =SUMIFS(Raw!M:M,Raw!A:A,Table2185[[#This Row],[Team]],Raw!B:B,Table2185[[#This Row],[Agent]]) -> 109.87 | H66: =(Table2185[[#This Row],[Num Escalations]]/Table2185[[#This Row],[Total calls Handled]]) -> 0.13017773 | I66: =SUMIFS(Raw!N:N,Raw!A:A,Table2185[[#This Row],[Team]],Raw!B:B,Table2185[[#This Row],[Agent]]) -> 687.12 | J66: =Table2185[[#This Row],[Num FCR]]/Table2185[[#This Row],[Total calls Handled]] -> 0.81412322 | K66: =AVERAGEIFS(Raw!J:J,Raw!A:A,Table2185[[#This Row],[Team]],Raw!B:B,Table2185[[#This Row],[Agent]]) -> 4.164
B67: Team C | C67: Agent_4 | D67: =SUMIFS(Raw!F:F, Raw!A:A, Table2185[[#This Row],[Team]], Raw!B:B, Table2185[[#This Row],[Agent]]) -> 915 | E67: =SUMIFS(Raw!G:G,Raw!A:A,Table2185[[#This Row],[Team]],Raw!B:B,Table2185[[#This Row],[Agent]]) -> 91.37 | F67: =AVERAGEIFS(Raw!L:L,Raw!A:A,B67,Raw!B:B,Table2185[[#This Row],[Agent]]) -> 25.336667 | G67: =SUMIFS(Raw!M:M,Raw!A:A,Table2185[[#This Row],[Team]],Raw!B:B,Table2185[[#This Row],[Agent]]) -> 92.5 | H67: =(Table2185[[#This Row],[Num Escalations]]/Table2185[[#This Row],[Total calls Handled]]) -> 0.1010929 | I67: =SUMIFS(Raw!N:N,Raw!A:A,Table2185[[#This Row],[Team]],Raw!B:B,Table2185[[#This Row],[Agent]]) -> 741.16 | J67: =Table2185[[#This Row],[Num FCR]]/Table2185[[#This Row],[Total calls Handled]] -> 0.81001093 | K67: =AVERAGEIFS(Raw!J:J,Raw!A:A,Table2185[[#This Row],[Team]],Raw!B:B,Table2185[[#This Row],[Agent]]) -> 4.264
B68: Team B | C68: Agent_5 | D68: =SUMIFS(Raw!F:F, Raw!A:A, Table2185[[#This Row],[Team]], Raw!B:B, Table2185[[#This Row],[Agent]]) -> 803 | E68: =SUMIFS(Raw!G:G,Raw!A:A,Table2185[[#This Row],[Team]],Raw!B:B,Table2185[[#This Row],[Agent]]) -> 115.22 | F68: =AVERAGEIFS(Raw!L:L,Raw!A:A,B68,Raw!B:B,Table2185[[#This Row],[Agent]]) -> 28.255333 | G68: =SUMIFS(Raw!M:M,Raw!A:A,Table2185[[#This Row],[Team]],Raw!B:B,Table2185[[#This Row],[Agent]]) -> 99.23 | H68: =(Table2185[[#This Row],[Num Escalations]]/Table2185[[#This Row],[Total calls Handled]]) -> 0.1235741 | I68: =SUMIFS(Raw!N:N,Raw!A:A,Table2185[[#This Row],[Team]],Raw!B:B,Table2185[[#This Row],[Agent]]) -> 650 | J68: =Table2185[[#This Row],[Num FCR]]/Table2185[[#This Row],[Total calls Handled]] -> 0.80946451 | K68: =AVERAGEIFS(Raw!J:J,Raw!A:A,Table2185[[#This Row],[Team]],Raw!B:B,Table2185[[#This Row],[Agent]]) -> 4.1513333
B69: Team B | C69: Agent_9 | D69: =SUMIFS(Raw!F:F, Raw!A:A, Table2185[[#This Row],[Team]], Raw!B:B, Table2185[[#This Row],[Agent]]) -> 755 | E69: =SUMIFS(Raw!G:G,Raw!A:A,Table2185[[#This Row],[Team]],Raw!B:B,Table2185[[#This Row],[Agent]]) -> 119.09 | F69: =AVERAGEIFS(Raw!L:L,Raw!A:A,B69,Raw!B:B,Table2185[[#This Row],[Agent]]) -> 28.11 | G69: =SUMIFS(Raw!M:M,Raw!A:A,Table2185[[#This Row],[Team]],Raw!B:B,Table2185[[#This Row],[Agent]]) -> 75.61 | H69: =(Table2185[[#This Row],[Num Escalations]]/Table2185[[#This Row],[Total calls Handled]]) -> 0.1001457 | I69: =SUMIFS(Raw!N:N,Raw!A:A,Table2185[[#This Row],[Team]],Raw!B:B,Table2185[[#This Row],[Agent]]) -> 610.29 | J69: =Table2185[[#This Row],[Num FCR]]/Table2185[[#This Row],[Total calls Handled]] -> 0.80833113 | K69: =AVERAGEIFS(Raw!J:J,Raw!A:A,Table2185[[#This Row],[Team]],Raw!B:B,Table2185[[#This Row],[Agent]]) -> 4.126
B70: Team A | C70: Agent_7 | D70: =SUMIFS(Raw!F:F, Raw!A:A, Table2185[[#This Row],[Team]], Raw!B:B, Table2185[[#This Row],[Agent]]) -> 697 | E70: =SUMIFS(Raw!G:G,Raw!A:A,Table2185[[#This Row],[Team]],Raw!B:B,Table2185[[#This Row],[Agent]]) -> 96.38 | F70: =AVERAGEIFS(Raw!L:L,Raw!A:A,B71,Raw!B:B,Table2185[[#This Row],[Agent]]) -> 25.171333 | G70: =SUMIFS(Raw!M:M,Raw!A:A,Table2185[[#This Row],[Team]],Raw!B:B,Table2185[[#This Row],[Agent]]) -> 70.74 | H70: =(Table2185[[#This Row],[Num Escalations]]/Table2185[[#This Row],[Total calls Handled]]) -> 0.10149211 | I70: =SUMIFS(Raw!N:N,Raw!A:A,Table2185[[#This Row],[Team]],Raw!B:B,Table2185[[#This Row],[Agent]]) -> 562.96 | J70: =Table2185[[#This Row],[Num FCR]]/Table2185[[#This Row],[Total calls Handled]] -> 0.8076901 | K70: =AVERAGEIFS(Raw!J:J,Raw!A:A,Table2185[[#This Row],[Team]],Raw!B:B,Table2185[[#This Row],[Agent]]) -> 4.1406667
B71: Team A | C71: Agent_6 | D71: =SUMIFS(Raw!F:F, Raw!A:A, Table2185[[#This Row],[Team]], Raw!B:B, Table2185[[#This Row],[Agent]]) -> 841 | E71: =SUMIFS(Raw!G:G,Raw!A:A,Table2185[[#This Row],[Team]],Raw!B:B,Table2185[[#This Row],[Agent]]) -> 89.85 | F71: =AVERAGEIFS(Raw!L:L,Raw!A:A,B72,Raw!B:B,Table2185[[#This Row],[Agent]]) -> 27.748 | G71: =SUMIFS(Raw!M:M,Raw!A:A,Table2185[[#This Row],[Team]],Raw!B:B,Table2185[[#This Row],[Agent]]) -> 80.23 | H71: =(Table2185[[#This Row],[Num Escalations]]/Table2185[[#This Row],[Total calls Handled]]) -> 0.095398335 | I71: =SUMIFS(Raw!N:N,Raw!A:A,Table2185[[#This Row],[Team]],Raw!B:B,Table2185[[#This Row],[Agent]]) -> 674.13 | J71: =Table2185[[#This Row],[Num FCR]]/Table2185[[#This Row],[Total calls Handled]] -> 0.80158145 | K71: =AVERAGEIFS(Raw!J:J,Raw!A:A,Table2185[[#This Row],[Team]],Raw!B:B,Table2185[[#This Row],[Agent]]) -> 4.3713333
B72: Team B | C72: Agent_8 | D72: =SUMIFS(Raw!F:F, Raw!A:A, Table2185[[#This Row],[Team]], Raw!B:B, Table2185[[#This Row],[Agent]]) -> 831 | E72: =SUMIFS(Raw!G:G,Raw!A:A,Table2185[[#This Row],[Team]],Raw!B:B,Table2185[[#This Row],[Agent]]) -> 112.01 | F72: =AVERAGEIFS(Raw!L:L,Raw!A:A,B72,Raw!B:B,Table2185[[#This Row],[Agent]]) -> 26.734667 | G72: =SUMIFS(Raw!M:M,Raw!A:A,Table2185[[#This Row],[Team]],Raw!B:B,Table2185[[#This Row],[Agent]]) -> 97.94 | H72: =(Table2185[[#This Row],[Num Escalations]]/Table2185[[#This Row],[Total calls Handled]]) -> 0.117858 | I72: =SUMIFS(Raw!N:N,Raw!A:A,Table2185[[#This Row],[Team]],Raw!B:B,Table2185[[#This Row],[Agent]]) -> 663.9 | J72: =Table2185[[#This Row],[Num FCR]]/Table2185[[#This Row],[Total calls Handled]] -> 0.79891697 | K72: =AVERAGEIFS(Raw!J:J,Raw!A:A,Table2185[[#This Row],[Team]],Raw!B:B,Table2185[[#This Row],[Agent]]) -> 4.1506667
B73: Team B | C73: Agent_3 | D73: =SUMIFS(Raw!F:F, Raw!A:A, Table2185[[#This Row],[Team]], Raw!B:B, Table2185[[#This Row],[Agent]]) -> 854 | E73: =SUMIFS(Raw!G:G,Raw!A:A,Table2185[[#This Row],[Team]],Raw!B:B,Table2185[[#This Row],[Agent]]) -> 114.51 | F73: =AVERAGEIFS(Raw!L:L,Raw!A:A,B73,Raw!B:B,Table2185[[#This Row],[Agent]]) -> 27.517333 | G73: =SUMIFS(Raw!M:M,Raw!A:A,Table2185[[#This Row],[Team]],Raw!B:B,Table2185[[#This Row],[Agent]]) -> 96.56 | H73: =(Table2185[[#This Row],[Num Escalations]]/Table2185[[#This Row],[Total calls Handled]]) -> 0.11306792 | I73: =SUMIFS(Raw!N:N,Raw!A:A,Table2185[[#This Row],[Team]],Raw!B:B,Table2185[[#This Row],[Agent]]) -> 678.59 | J73: =Table2185[[#This Row],[Num FCR]]/Table2185[[#This Row],[Total calls Handled]] -> 0.79460187 | K73: =AVERAGEIFS(Raw!J:J,Raw!A:A,Table2185[[#This Row],[Team]],Raw!B:B,Table2185[[#This Row],[Agent]]) -> 4.148
B74: Team A | C74: Agent_3 | D74: =SUMIFS(Raw!F:F, Raw!A:A, Table2185[[#This Row],[Team]], Raw!B:B, Table2185[[#This Row],[Agent]]) -> 882 | E74: =SUMIFS(Raw!G:G,Raw!A:A,Table2185[[#This Row],[Team]],Raw!B:B,Table2185[[#This Row],[Agent]]) -> 93.8 | F74: =AVERAGEIFS(Raw!L:L,Raw!A:A,B75,Raw!B:B,Table2185[[#This Row],[Agent]]) -> 25.313333 | G74: =SUMIFS(Raw!M:M,Raw!A:A,Table2185[[#This Row],[Team]],Raw!B:B,Table2185[[#This Row],[Agent]]) -> 115.83 | H74: =(Table2185[[#This Row],[Num Escalations]]/Table2185[[#This Row],[Total calls Handled]]) -> 0.13132653 | I74: =SUMIFS(Raw!N:N,Raw!A:A,Table2185[[#This Row],[Team]],Raw!B:B,Table2185[[#This Row],[Agent]]) -> 699.08 | J74: =Table2185[[#This Row],[Num FCR]]/Table2185[[#This Row],[Total calls Handled]] -> 0.79260771 | K74: =AVERAGEIFS(Raw!J:J,Raw!A:A,Table2185[[#This Row],[Team]],Raw!B:B,Table2185[[#This Row],[Agent]]) -> 4.1206667
B75: Team A | C75: Agent_10 | D75: =SUMIFS(Raw!F:F, Raw!A:A, Table2185[[#This Row],[Team]], Raw!B:B, Table2185[[#This Row],[Agent]]) -> 814 | E75: =SUMIFS(Raw!G:G,Raw!A:A,Table2185[[#This Row],[Team]],Raw!B:B,Table2185[[#This Row],[Agent]]) -> 87.82 | F75: =AVERAGEIFS(Raw!L:L,Raw!A:A,Table2185[[#This Row],[Team]],Raw!B:B,Table2185[[#This Row],[Agent]]) -> 25.249333 | G75: =SUMIFS(Raw!M:M,Raw!A:A,Table2185[[#This Row],[Team]],Raw!B:B,Table2185[[#This Row],[Agent]]) -> 126.73 | H75: =(Table2185[[#This Row],[Num Escalations]]/Table2185[[#This Row],[Total calls Handled]]) -> 0.15568796 | I75: =SUMIFS(Raw!N:N,Raw!A:A,Table2185[[#This Row],[Team]],Raw!B:B,Table2185[[#This Row],[Agent]]) -> 644.59 | J75: =Table2185[[#This Row],[Num FCR]]/Table2185[[#This Row],[Total calls Handled]] -> 0.79187961 | K75: =AVERAGEIFS(Raw!J:J,Raw!A:A,Table2185[[#This Row],[Team]],Raw!B:B,Table2185[[#This Row],[Agent]]) -> 4.3493333
B76: Team C | C76: Agent_2 | D76: =SUMIFS(Raw!F:F, Raw!A:A, Table2185[[#This Row],[Team]], Raw!B:B, Table2185[[#This Row],[Agent]]) -> 758 | E76: =SUMIFS(Raw!G:G,Raw!A:A,Table2185[[#This Row],[Team]],Raw!B:B,Table2185[[#This Row],[Agent]]) -> 93.88 | F76: =AVERAGEIFS(Raw!L:L,Raw!A:A,B76,Raw!B:B,Table2185[[#This Row],[Agent]]) -> 25.454 | G76: =SUMIFS(Raw!M:M,Raw!A:A,Table2185[[#This Row],[Team]],Raw!B:B,Table2185[[#This Row],[Agent]]) -> 100.81 | H76: =(Table2185[[#This Row],[Num Escalations]]/Table2185[[#This Row],[Total calls Handled]]) -> 0.13299472 | I76: =SUMIFS(Raw!N:N,Raw!A:A,Table2185[[#This Row],[Team]],Raw!B:B,Table2185[[#This Row],[Agent]]) -> 599.88 | J76: =Table2185[[#This Row],[Num FCR]]/Table2185[[#This Row],[Total calls Handled]] -> 0.79139842 | K76: =AVERAGEIFS(Raw!J:J,Raw!A:A,Table2185[[#This Row],[Team]],Raw!B:B,Table2185[[#This Row],[Agent]]) -> 4.0853333
...
